Traceback (most recent call last):
  File "./CI/prediction_deploy.py", line 31, in <module>
    app.run( host="0.0.0.0", port=8082)
  File "/Library/Frameworks/Python.framework/Versions/3.6/lib/python3.6/site-packages/flask/app.py", line 841, in run
    run_simple(host, port, self, **options)
  File "/Library/Frameworks/Python.framework/Versions/3.6/lib/python3.6/site-packages/werkzeug/serving.py", line 1052, in run_simple
    inner()
  File "/Library/Frameworks/Python.framework/Versions/3.6/lib/python3.6/site-packages/werkzeug/serving.py", line 1005, in inner
    fd=fd,
  File "/Library/Frameworks/Python.framework/Versions/3.6/lib/python3.6/site-packages/werkzeug/serving.py", line 863, in make_server
    host, port, app, request_handler, passthrough_errors, ssl_context, fd=fd
  File "/Library/Frameworks/Python.framework/Versions/3.6/lib/python3.6/site-packages/werkzeug/serving.py", line 740, in __init__
    HTTPServer.__init__(self, server_address, handler)
  File "/Library/Frameworks/Python.framework/Versions/3.6/lib/python3.6/socketserver.py", line 453, in __init__
    self.server_bind()
  File "/Library/Frameworks/Python.framework/Versions/3.6/lib/python3.6/http/server.py", line 136, in server_bind
    socketserver.TCPServer.server_bind(self)
  File "/Library/Frameworks/Python.framework/Versions/3.6/lib/python3.6/socketserver.py", line 467, in server_bind
    self.socket.bind(self.server_address)
OSError: [Errno 48] Address already in use
